Workbook
Name AssetM: [1]Table!$J$3:$K$13
Name Benjamin: OFFSET('[2]Weight Watch'!$B$9,'[2]Weight Watch'!$I$3-9,2,'[2]Weight Watch'!$I$2,1)
Name Client: [1]X!$C$9
Name DateF: OFFSET('[2]Weight Watch'!$B$9,'[2]Weight Watch'!$I$3-9,0,'[2]Weight Watch'!$I$2,1)
Name DefaultB: [1]X!$F$5
Name Difference: OFFSET([3]Salman!$G$9,0,0,[3]Salman!$B$4,1)
Name Eric: OFFSET('[2]Weight Watch'!$B$9,'[2]Weight Watch'!$I$3-9,4,'[2]Weight Watch'!$I$2,1)
Name FanF: OFFSET('[2]Weight Watch'!$B$9,'[2]Weight Watch'!$I$3-9,3,'[2]Weight Watch'!$I$2,1)
Name Footer: [1]X!$C$10
Name George: OFFSET('[2]Weight Watch'!$B$9,'[2]Weight Watch'!$I$3-9,3,'[2]Weight Watch'!$I$2,1)
Name LiF: OFFSET('[2]Weight Watch'!$B$9,'[2]Weight Watch'!$I$3-9,2,'[2]Weight Watch'!$I$2,1)
Name MeasDate: OFFSET('[2]Weight Watch'!$B$9,'[2]Weight Watch'!$I$3-9,0,'[2]Weight Watch'!$I$2,1)
Name MetMRV: [4]Table!$C$21:$D$31
Name Rate: OFFSET([5]Rate!$C$4,0,0,COUNT([5]Rate!$C:$C))
Name Version: [1]X!$A$2
Name WangF: OFFSET('[2]Weight Watch'!$B$9,'[2]Weight Watch'!$I$3-9,4,'[2]Weight Watch'!$I$2,1)
Name Year: OFFSET([5]Rate!$B$4,0,0,COUNT([5]Rate!$B:$B))
Name Year158: '[6]FAS 158 Input'!$H$4

Sheet Benefits
B2: Input Information
B3: Average Salary | H3: 60000
B4: Percentage for each year of service | H4: 0.03
B5: Early retirement reduction percentage | H5: 0.04
B6: Late retirment increase percentage | H6: 0.05
B7: Normal retirement age | H7: 65
B8: Early retirement eligibility provisions
B9: Age requirement for early retirement | H9: 55
B10: Service requirement for early retirement | H10: 15
B12: defaults
B13: Average Salary | H13: =IF(ISBLANK(H3),60000,H3) -> 60000
B14: Percentage for each year of service | H14: =IF(ISBLANK(H4),0.03,H4) -> 0.03
B15: Early retirement reduction percentage | H15: =IF(ISBLANK(H5),0.04,H5) -> 0.04
B16: Late retirment increase percentage | H16: =IF(ISBLANK(H6),0.05,H6) -> 0.05
B17: Normal retirement age | H17: =IF(ISBLANK(H7),65,H7) -> 65
B18: Age requirement for early retirement | H18: =IF(ISBLANK(H9),55,H9) -> 55
B19: Service requirement for early retirement | H19: =IF(ISBLANK(H10),10,H10) -> 15
B21: Retirement Benefit at Each Retirement Age
B22: ="Normal Retirement Age: "&H17 -> Normal Retirement Age: 65
B23: ="Early Retirement Requirements: Age "&H18&" with 10 years of Service" -> Early Retirement Requirements: Age 55 with 10 years of Service
B24: Years of Service | C24: Retirement Age
C25: 70 | D25: 65 | E25: 62 | F25: 60 | G25: 55 | H25: 50
B26: 5 | C26: =IF(C$25>=$H$17, $H$13*$H$14*$B26*(1-$H$16*($H$17-C$25)), IF(OR(C$25<$H$18,$B26<$H$19),0,$H$13*$H$14*$B26*(1-$H$15*($H$17-C$25)))) -> 11250 | D26: =IF(D$25>=$H$17, $H$13*$H$14*$B26*(1-$H$16*($H$17-D$25)), IF(OR(D$25<$H$18,$B26<$H$19),0,$H$13*$H$14*$B26*(1-$H$15*($H$17-D$25)))) -> 9000 | E26: =IF(E$25>=$H$17, $H$13*$H$14*$B26*(1-$H$16*($H$17-E$25)), IF(OR(E$25<$H$18,$B26<$H$19),0,$H$13*$H$14*$B26*(1-$H$15*($H$17-E$25)))) -> 0 | F26: =IF(F$25>=$H$17, $H$13*$H$14*$B26*(1-$H$16*($H$17-F$25)), IF(OR(F$25<$H$18,$B26<$H$19),0,$H$13*$H$14*$B26*(1-$H$15*($H$17-F$25)))) -> 0 | G26: =IF(G$25>=$H$17, $H$13*$H$14*$B26*(1-$H$16*($H$17-G$25)), IF(OR(G$25<$H$18,$B26<$H$19),0,$H$13*$H$14*$B26*(1-$H$15*($H$17-G$25)))) -> 0 | H26: =IF(H$25>=$H$17, $H$13*$H$14*$B26*(1-$H$16*($H$17-H$25)), IF(OR(H$25<$H$18,$B26<$H$19),0,$H$13*$H$14*$B26*(1-$H$15*($H$17-H$25)))) -> 0
B27: 10 | C27: =IF(C$25>=$H$17, $H$13*$H$14*$B27*(1-$H$16*($H$17-C$25)), IF(OR(C$25<$H$18,$B27<$H$19),0,$H$13*$H$14*$B27*(1-$H$15*($H$17-C$25)))) -> 22500 | D27: =IF(D$25>=$H$17, $H$13*$H$14*$B27*(1-$H$16*($H$17-D$25)), IF(OR(D$25<$H$18,$B27<$H$19),0,$H$13*$H$14*$B27*(1-$H$15*($H$17-D$25)))) -> 18000 | E27: =IF(E$25>=$H$17, $H$13*$H$14*$B27*(1-$H$16*($H$17-E$25)), IF(OR(E$25<$H$18,$B27<$H$19),0,$H$13*$H$14*$B27*(1-$H$15*($H$17-E$25)))) -> 0 | F27: =IF(F$25>=$H$17, $H$13*$H$14*$B27*(1-$H$16*($H$17-F$25)), IF(OR(F$25<$H$18,$B27<$H$19),0,$H$13*$H$14*$B27*(1-$H$15*($H$17-F$25)))) -> 0 | G27: =IF(G$25>=$H$17, $H$13*$H$14*$B27*(1-$H$16*($H$17-G$25)), IF(OR(G$25<$H$18,$B27<$H$19),0,$H$13*$H$14*$B27*(1-$H$15*($H$17-G$25)))) -> 0 | H27: =IF(H$25>=$H$17, $H$13*$H$14*$B27*(1-$H$16*($H$17-H$25)), IF(OR(H$25<$H$18,$B27<$H$19),0,$H$13*$H$14*$B27*(1-$H$15*($H$17-H$25)))) -> 0
B28: 15 | C28: =IF(C$25>=$H$17, $H$13*$H$14*$B28*(1-$H$16*($H$17-C$25)), IF(OR(C$25<$H$18,$B28<$H$19),0,$H$13*$H$14*$B28*(1-$H$15*($H$17-C$25)))) -> 33750 | D28: =IF(D$25>=$H$17, $H$13*$H$14*$B28*(1-$H$16*($H$17-D$25)), IF(OR(D$25<$H$18,$B28<$H$19),0,$H$13*$H$14*$B28*(1-$H$15*($H$17-D$25)))) -> 27000 | E28: =IF(E$25>=$H$17, $H$13*$H$14*$B28*(1-$H$16*($H$17-E$25)), IF(OR(E$25<$H$18,$B28<$H$19),0,$H$13*$H$14*$B28*(1-$H$15*($H$17-E$25)))) -> 23760 | F28: =IF(F$25>=$H$17, $H$13*$H$14*$B28*(1-$H$16*($H$17-F$25)), IF(OR(F$25<$H$18,$B28<$H$19),0,$H$13*$H$14*$B28*(1-$H$15*($H$17-F$25)))) -> 21600 | G28: =IF(G$25>=$H$17, $H$13*$H$14*$B28*(1-$H$16*($H$17-G$25)), IF(OR(G$25<$H$18,$B28<$H$19),0,$H$13*$H$14*$B28*(1-$H$15*($H$17-G$25)))) -> 16200 | H28: =IF(H$25>=$H$17, $H$13*$H$14*$B28*(1-$H$16*($H$17-H$25)), IF(OR(H$25<$H$18,$B28<$H$19),0,$H$13*$H$14*$B28*(1-$H$15*($H$17-H$25)))) -> 0
B29: 20 | C29: =IF(C$25>=$H$17, $H$13*$H$14*$B29*(1-$H$16*($H$17-C$25)), IF(OR(C$25<$H$18,$B29<$H$19),0,$H$13*$H$14*$B29*(1-$H$15*($H$17-C$25)))) -> 45000 | D29: =IF(D$25>=$H$17, $H$13*$H$14*$B29*(1-$H$16*($H$17-D$25)), IF(OR(D$25<$H$18,$B29<$H$19),0,$H$13*$H$14*$B29*(1-$H$15*($H$17-D$25)))) -> 36000 | E29: =IF(E$25>=$H$17, $H$13*$H$14*$B29*(1-$H$16*($H$17-E$25)), IF(OR(E$25<$H$18,$B29<$H$19),0,$H$13*$H$14*$B29*(1-$H$15*($H$17-E$25)))) -> 31680 | F29: =IF(F$25>=$H$17, $H$13*$H$14*$B29*(1-$H$16*($H$17-F$25)), IF(OR(F$25<$H$18,$B29<$H$19),0,$H$13*$H$14*$B29*(1-$H$15*($H$17-F$25)))) -> 28800 | G29: =IF(G$25>=$H$17, $H$13*$H$14*$B29*(1-$H$16*($H$17-G$25)), IF(OR(G$25<$H$18,$B29<$H$19),0,$H$13*$H$14*$B29*(1-$H$15*($H$17-G$25)))) -> 21600 | H29: =IF(H$25>=$H$17, $H$13*$H$14*$B29*(1-$H$16*($H$17-H$25)), IF(OR(H$25<$H$18,$B29<$H$19),0,$H$13*$H$14*$B29*(1-$H$15*($H$17-H$25)))) -> 0
B30: 25 | C30: =IF(C$25>=$H$17, $H$13*$H$14*$B30*(1-$H$16*($H$17-C$25)), IF(OR(C$25<$H$18,$B30<$H$19),0,$H$13*$H$14*$B30*(1-$H$15*($H$17-C$25)))) -> 56250 | D30: =IF(D$25>=$H$17, $H$13*$H$14*$B30*(1-$H$16*($H$17-D$25)), IF(OR(D$25<$H$18,$B30<$H$19),0,$H$13*$H$14*$B30*(1-$H$15*($H$17-D$25)))) -> 45000 | E30: =IF(E$25>=$H$17, $H$13*$H$14*$B30*(1-$H$16*($H$17-E$25)), IF(OR(E$25<$H$18,$B30<$H$19),0,$H$13*$H$14*$B30*(1-$H$15*($H$17-E$25)))) -> 39600 | F30: =IF(F$25>=$H$17, $H$13*$H$14*$B30*(1-$H$16*($H$17-F$25)), IF(OR(F$25<$H$18,$B30<$H$19),0,$H$13*$H$14*$B30*(1-$H$15*($H$17-F$25)))) -> 36000 | G30: =IF(G$25>=$H$17, $H$13*$H$14*$B30*(1-$H$16*($H$17-G$25)), IF(OR(G$25<$H$18,$B30<$H$19),0,$H$13*$H$14*$B30*(1-$H$15*($H$17-G$25)))) -> 27000 | H30: =IF(H$25>=$H$17, $H$13*$H$14*$B30*(1-$H$16*($H$17-H$25)), IF(OR(H$25<$H$18,$B30<$H$19),0,$H$13*$H$14*$B30*(1-$H$15*($H$17-H$25)))) -> 0
B31: 30 | C31: =IF(C$25>=$H$17, $H$13*$H$14*$B31*(1-$H$16*($H$17-C$25)), IF(OR(C$25<$H$18,$B31<$H$19),0,$H$13*$H$14*$B31*(1-$H$15*($H$17-C$25)))) -> 67500 | D31: =IF(D$25>=$H$17, $H$13*$H$14*$B31*(1-$H$16*($H$17-D$25)), IF(OR(D$25<$H$18,$B31<$H$19),0,$H$13*$H$14*$B31*(1-$H$15*($H$17-D$25)))) -> 54000 | E31: =IF(E$25>=$H$17, $H$13*$H$14*$B31*(1-$H$16*($H$17-E$25)), IF(OR(E$25<$H$18,$B31<$H$19),0,$H$13*$H$14*$B31*(1-$H$15*($H$17-E$25)))) -> 47520 | F31: =IF(F$25>=$H$17, $H$13*$H$14*$B31*(1-$H$16*($H$17-F$25)), IF(OR(F$25<$H$18,$B31<$H$19),0,$H$13*$H$14*$B31*(1-$H$15*($H$17-F$25)))) -> 43200 | G31: =IF(G$25>=$H$17, $H$13*$H$14*$B31*(1-$H$16*($H$17-G$25)), IF(OR(G$25<$H$18,$B31<$H$19),0,$H$13*$H$14*$B31*(1-$H$15*($H$17-G$25)))) -> 32400 | H31: =IF(H$25>=$H$17, $H$13*$H$14*$B31*(1-$H$16*($H$17-H$25)), IF(OR(H$25<$H$18,$B31<$H$19),0,$H$13*$H$14*$B31*(1-$H$15*($H$17-H$25)))) -> 0
B32: 35 | C32: =IF(C$25>=$H$17, $H$13*$H$14*$B32*(1-$H$16*($H$17-C$25)), IF(OR(C$25<$H$18,$B32<$H$19),0,$H$13*$H$14*$B32*(1-$H$15*($H$17-C$25)))) -> 78750 | D32: =IF(D$25>=$H$17, $H$13*$H$14*$B32*(1-$H$16*($H$17-D$25)), IF(OR(D$25<$H$18,$B32<$H$19),0,$H$13*$H$14*$B32*(1-$H$15*($H$17-D$25)))) -> 63000 | E32: =IF(E$25>=$H$17, $H$13*$H$14*$B32*(1-$H$16*($H$17-E$25)), IF(OR(E$25<$H$18,$B32<$H$19),0,$H$13*$H$14*$B32*(1-$H$15*($H$17-E$25)))) -> 55440 | F32: =IF(F$25>=$H$17, $H$13*$H$14*$B32*(1-$H$16*($H$17-F$25)), IF(OR(F$25<$H$18,$B32<$H$19),0,$H$13*$H$14*$B32*(1-$H$15*($H$17-F$25)))) -> 50400 | G32: =IF(G$25>=$H$17, $H$13*$H$14*$B32*(1-$H$16*($H$17-G$25)), IF(OR(G$25<$H$18,$B32<$H$19),0,$H$13*$H$14*$B32*(1-$H$15*($H$17-G$25)))) -> 37800 | H32: =IF(H$25>=$H$17, $H$13*$H$14*$B32*(1-$H$16*($H$17-H$25)), IF(OR(H$25<$H$18,$B32<$H$19),0,$H$13*$H$14*$B32*(1-$H$15*($H$17-H$25)))) -> 0

Sheet Distributions
B2: Highlighted cells for ages are the only input cells
B4: Age Breakpoint | F4: Distribution by Age with total and Average Salary
B5: Age is | F5: (Actives Only)
B6: at least | C6: but | D6: less than | F6: Age | G6: Count | H6: Total Salary | I6: Average Salary
B7: =D7-D7 -> 0 | D7: 20 | F7: =IF(AND(OR($B7=0,$B7=""),OR($B8=0,$B8="")),"",IF(OR($B8="",$B8=0),$B7&" <=",IF($B7=0,"< "&$B8,$B7&" - "&$B8))) -> < 20 | G7: =IF(AND($B7="",$B8=""),"",IF($B8="",COUNTIFS(EeData!$G:$G,"A",EeData!$E:$E,">="&$B7),COUNTIFS(EeData!$G:$G,"A",EeData!$E:$E,">="&$B7,EeData!$E:$E,"<"&$B8))) -> 0 | H7: =IF(B7="","",IF(D7="",SUMIFS(EeData!C:C,EeData!G:G,"A",EeData!E:E,">="&B7),SUMIFS(EeData!C:C,EeData!G:G,"A",EeData!E:E,">="&B7,EeData!E:E,"<"&D7))) -> 0 | I7: =IF(G7 = "", "", IF(G7=0,0,$H7/$G7)) -> 0
B8: =IF(ISBLANK(D7),"", D7) -> 20 | D8: 30 | F8: =IF(AND(OR($B8=0,$B8=""),OR($B9=0,$B9="")),"",IF(OR($B9="",$B9=0),$B8&" <=",IF($B8=0,"< "&$B9,$B8&" - "&$B9))) -> 20 - 30 | G8: =IF(AND($B8="",$B9=""),"",IF($B9="",COUNTIFS(EeData!$G:$G,"A",EeData!$E:$E,">="&$B8),COUNTIFS(EeData!$G:$G,"A",EeData!$E:$E,">="&$B8,EeData!$E:$E,"<"&$B9))) -> 3 | H8: =IF(B8="","",IF(D8="",SUMIFS(EeData!C:C,EeData!G:G,"A",EeData!E:E,">="&B8),SUMIFS(EeData!C:C,EeData!G:G,"A",EeData!E:E,">="&B8,EeData!E:E,"<"&D8))) -> 248000 | I8: =IF(G8 = "", "", IF(G8=0,0,$H8/$G8)) -> 82666.667
B9: =IF(ISBLANK(D8),"", D8) -> 30 | D9: 40 | F9: =IF(AND(OR($B9=0,$B9=""),OR($B10=0,$B10="")),"",IF(OR($B10="",$B10=0),$B9&" <=",IF($B9=0,"< "&$B10,$B9&" - "&$B10))) -> 30 - 40 | G9: =IF(AND($B9="",$B10=""),"",IF($B10="",COUNTIFS(EeData!$G:$G,"A",EeData!$E:$E,">="&$B9),COUNTIFS(EeData!$G:$G,"A",EeData!$E:$E,">="&$B9,EeData!$E:$E,"<"&$B10))) -> 11 | H9: =IF(B9="","",IF(D9="",SUMIFS(EeData!C:C,EeData!G:G,"A",EeData!E:E,">="&B9),SUMIFS(EeData!C:C,EeData!G:G,"A",EeData!E:E,">="&B9,EeData!E:E,"<"&D9))) -> 1011000 | I9: =IF(G9 = "", "", IF(G9=0,0,$H9/$G9)) -> 91909.091
B10: =IF(ISBLANK(D9),"", D9) -> 40 | D10: 50 | F10: =IF(AND(OR($B10=0,$B10=""),OR($B11=0,$B11="")),"",IF(OR($B11="",$B11=0),$B10&" <=",IF($B10=0,"< "&$B11,$B10&" - "&$B11))) -> 40 - 50 | G10: =IF(AND($B10="",$B11=""),"",IF($B11="",COUNTIFS(EeData!$G:$G,"A",EeData!$E:$E,">="&$B10),COUNTIFS(EeData!$G:$G,"A",EeData!$E:$E,">="&$B10,EeData!$E:$E,"<"&$B11))) -> 13 | H10: =IF(B10="","",IF(D10="",SUMIFS(EeData!C:C,EeData!G:G,"A",EeData!E:E,">="&B10),SUMIFS(EeData!C:C,EeData!G:G,"A",EeData!E:E,">="&B10,EeData!E:E,"<"&D10))) -> 1150000 | I10: =IF(G10 = "", "", IF(G10=0,0,$H10/$G10)) -> 88461.538
B11: =IF(ISBLANK(D10),"", D10) -> 50 | D11: 60 | F11: =IF(AND(OR($B11=0,$B11=""),OR($B12=0,$B12="")),"",IF(OR($B12="",$B12=0),$B11&" <=",IF($B11=0,"< "&$B12,$B11&" - "&$B12))) -> 50 - 60 | G11: =IF(AND($B11="",$B12=""),"",IF($B12="",COUNTIFS(EeData!$G:$G,"A",EeData!$E:$E,">="&$B11),COUNTIFS(EeData!$G:$G,"A",EeData!$E:$E,">="&$B11,EeData!$E:$E,"<"&$B12))) -> 9 | H11: =IF(B11="","",IF(D11="",SUMIFS(EeData!C:C,EeData!G:G,"A",EeData!E:E,">="&B11),SUMIFS(EeData!C:C,EeData!G:G,"A",EeData!E:E,">="&B11,EeData!E:E,"<"&D11))) -> 1209000 | I11: =IF(G11 = "", "", IF(G11=0,0,$H11/$G11)) -> 134333.33
B12: =IF(ISBLANK(D11),"", D11) -> 60 | F12: =IF(AND(OR($B12=0,$B12=""),OR($B13=0,$B13="")),"",IF(OR($B13="",$B13=0),$B12&" <=",IF($B12=0,"< "&$B13,$B12&" - "&$B13))) -> 60 <= | G12: =IF(AND($B12="",$B13=""),"",IF($B13="",COUNTIFS(EeData!$G:$G,"A",EeData!$E:$E,">="&$B12),COUNTIFS(EeData!$G:$G,"A",EeData!$E:$E,">="&$B12,EeData!$E:$E,"<"&$B13))) -> 1 | H12: =IF(B12="","",IF(D12="",SUMIFS(EeData!C:C,EeData!G:G,"A",EeData!E:E,">="&B12),SUMIFS(EeData!C:C,EeData!G:G,"A",EeData!E:E,">="&B12,EeData!E:E,"<"&D12))) -> 86000 | I12: =IF(G12 = "", "", IF(G12=0,0,$H12/$G12)) -> 86000
B13: =IF(ISBLANK(D12),"", D12) | F13: =IF(AND(OR($B13=0,$B13=""),OR($B14=0,$B14="")),"",IF(OR($B14="",$B14=0),$B13&" <=",IF($B13=0,"< "&$B14,$B13&" - "&$B14))) | G13: =IF(AND($B13="",$B14=""),"",IF($B14="",COUNTIFS(EeData!$G:$G,"A",EeData!$E:$E,">="&$B13),COUNTIFS(EeData!$G:$G,"A",EeData!$E:$E,">="&$B13,EeData!$E:$E,"<"&$B14))) | H13: =IF(B13="","",IF(D13="",SUMIFS(EeData!C:C,EeData!G:G,"A",EeData!E:E,">="&B13),SUMIFS(EeData!C:C,EeData!G:G,"A",EeData!E:E,">="&B13,EeData!E:E,"<"&D13))) | I13: =IF(G13 = "", "", IF(G13=0,0,$H13/$G13))
B14: =IF(ISBLANK(D13),"", D13) | F14: =IF(AND(OR($B14=0,$B14=""),OR($B15=0,$B15="")),"",IF(OR($B15="",$B15=0),$B14&" <=",IF($B14=0,"< "&$B15,$B14&" - "&$B15))) | G14: =IF(AND($B14="",$B15=""),"",IF($B15="",COUNTIFS(EeData!$G:$G,"A",EeData!$E:$E,">="&$B14),COUNTIFS(EeData!$G:$G,"A",EeData!$E:$E,">="&$B14,EeData!$E:$E,"<"&$B15))) | H14: =IF(B14="","",IF(D14="",SUMIFS(EeData!C:C,EeData!G:G,"A",EeData!E:E,">="&B14),SUMIFS(EeData!C:C,EeData!G:G,"A",EeData!E:E,">="&B14,EeData!E:E,"<"&D14))) | I14: =IF(G14 = "", "", IF(G14=0,0,$H14/$G14))
B15: =IF(ISBLANK(D14),"", D14) | F15: =IF(AND(OR($B15=0,$B15=""),OR($B16=0,$B16="")),"",IF(OR($B16="",$B16=0),$B15&" <=",IF($B15=0,"< "&$B16,$B15&" - "&$B16))) | G15: =IF(AND($B15="",$B16=""),"",IF($B16="",COUNTIFS(EeData!$G:$G,"A",EeData!$E:$E,">="&$B15),COUNTIFS(EeData!$G:$G,"A",EeData!$E:$E,">="&$B15,EeData!$E:$E,"<"&$B16))) | H15: =IF(B15="","",IF(D15="",SUMIFS(EeData!C:C,EeData!G:G,"A",EeData!E:E,">="&B15),SUMIFS(EeData!C:C,EeData!G:G,"A",EeData!E:E,">="&B15,EeData!E:E,"<"&D15))) | I15: =IF(G15 = "", "", IF(G15=0,0,$H15/$G15))
B16: =IF(ISBLANK(D15),"", D15) | F16: =IF(AND(OR($B16=0,$B16=""),OR($B17=0,$B17="")),"",IF(OR($B17="",$B17=0),$B16&" <=",IF($B16=0,"< "&$B17,$B16&" - "&$B17))) | G16: =IF(AND($B16="",$B17=""),"",IF($B17="",COUNTIFS(EeData!$G:$G,"A",EeData!$E:$E,">="&$B16),COUNTIFS(EeData!$G:$G,"A",EeData!$E:$E,">="&$B16,EeData!$E:$E,"<"&$B17))) | H16: =IF(B16="","",IF(D16="",SUMIFS(EeData!C:C,EeData!G:G,"A",EeData!E:E,">="&B16),SUMIFS(EeData!C:C,EeData!G:G,"A",EeData!E:E,">="&B16,EeData!E:E,"<"&D16))) | I16: =IF(G16 = "", "", IF(G16=0,0,$H16/$G16))
B17: =IF(ISBLANK(D16),"", D16) | G17: =IF(AND($B17="",$B18=""),"",IF($B18="",COUNTIFS(EeData!$G:$G,"A",EeData!$E:$E,">="&$B17),COUNTIFS(EeData!$G:$G,"A",EeData!$E:$E,">="&$B17,EeData!$E:$E,"<"&$B18))) | H17: =IF(B17="","",IF(D17="",SUMIFS(EeData!C:C,EeData!G:G,"A",EeData!E:E,">="&B17),SUMIFS(EeData!C:C,EeData!G:G,"A",EeData!E:E,">="&B17,EeData!E:E,"<"&D17))) | I17: =IF(G17 = "", "", IF(G17=0,0,$H17/$G17))
B18: =IF(ISBLANK(D17),"", D17) | F18: =IF(AND(OR($B18=0,$B18=""),OR($B19=0,$B19="")),"",IF(OR($B19="",$B19=0),$B18&" <=",IF($B18=0,"< "&$B19,$B18&" - "&$B19))) | G18: =IF(AND($B18="",$B19=""),"",IF($B19="",COUNTIFS(EeData!$G:$G,"A",EeData!$E:$E,">="&$B18),COUNTIFS(EeData!$G:$G,"A",EeData!$E:$E,">="&$B18,EeData!$E:$E,"<"&$B19))) | H18: =IF(B18="","",IF(D18="",SUMIFS(EeData!C:C,EeData!G:G,"A",EeData!E:E,">="&B18),SUMIFS(EeData!C:C,EeData!G:G,"A",EeData!E:E,">="&B18,EeData!E:E,"<"&D18))) | I18: =IF(G18 = "", "", IF(G18=0,0,$H18/$G18))
B19: =IF(ISBLANK(D18),"", D18) | F19: =IF(AND(OR($B19=0,$B19=""),OR($B20=0,$B20="")),"",IF(OR($B20="",$B20=0),$B19&" <=",IF($B19=0,"< "&$B20,$B19&" - "&$B20))) | G19: =IF(AND($B19="",$B20=""),"",IF($B20="",COUNTIFS(EeData!$G:$G,"A",EeData!$E:$E,">="&$B19),COUNTIFS(EeData!$G:$G,"A",EeData!$E:$E,">="&$B19,EeData!$E:$E,"<"&$B20))) | H19: =IF(B19="","",IF(D19="",SUMIFS(EeData!C:C,EeData!G:G,"A",EeData!E:E,">="&B19),SUMIFS(EeData!C:C,EeData!G:G,"A",EeData!E:E,">="&B19,EeData!E:E,"<"&D19))) | I19: =IF(G19 = "", "", IF(G19=0,0,$H19/$G19))
B20: =IF(ISBLANK(D19),"", D19) | F20: =IF(AND(OR($B20=0,$B20=""),OR($B21=0,$B21="")),"",IF(OR($B21="",$B21=0),$B20&" <=",IF($B20=0,"< "&$B21,$B20&" - "&$B21))) | G20: =IF(AND($B20="",$B21=""),"",IF($B21="",COUNTIFS(EeData!$G:$G,"A",EeData!$E:$E,">="&$B20),COUNTIFS(EeData!$G:$G,"A",EeData!$E:$E,">="&$B20,EeData!$E:$E,"<"&$B21))) | H20: =IF(B20="","",IF(D20="",SUMIFS(EeData!C:C,EeData!G:G,"A",EeData!E:E,">="&B20),SUMIFS(EeData!C:C,EeData!G:G,"A",EeData!E:E,">="&B20,EeData!E:E,"<"&D20))) | I20: =IF(G20 = "", "", IF(G20=0,0,$H20/$G20))
B21: =IF(ISBLANK(D20),"", D20) | F21: =IF(AND(OR($B21=0,$B21=""),OR($B22=0,$B22="")),"",IF(OR($B22="",$B22=0),$B21&" <=",IF($B21=0,"< "&$B22,$B21&" - "&$B22))) | G21: =IF(AND($B21="",$B22=""),"",IF($B22="",COUNTIFS(EeData!$G:$G,"A",EeData!$E:$E,">="&$B21),COUNTIFS(EeData!$G:$G,"A",EeData!$E:$E,">="&$B21,EeData!$E:$E,"<"&$B22))) | H21: =IF(B21="","",IF(D21="",SUMIFS(EeData!C:C,EeData!G:G,"A",EeData!E:E,">="&B21),SUMIFS(EeData!C:C,EeData!G:G,"A",EeData!E:E,">="&B21,EeData!E:E,"<"&D21))) | I21: =IF(G21 = "", "", IF(G21=0,0,$H21/$G21))
B22: =IF(ISBLANK(D21),"", D21) | F22: =IF(AND(OR($B22=0,$B22=""),OR($B23=0,$B23="")),"",IF(OR($B23="",$B23=0),$B22&" <=",IF($B22=0,"< "&$B23,$B22&" - "&$B23))) | G22: =IF(AND($B22="",$B23=""),"",IF($B23="",COUNTIFS(EeData!$G:$G,"A",EeData!$E:$E,">="&$B22),COUNTIFS(EeData!$G:$G,"A",EeData!$E:$E,">="&$B22,EeData!$E:$E,"<"&$B23))) | H22: =IF(B22="","",IF(D22="",SUMIFS(EeData!C:C,EeData!G:G,"A",EeData!E:E,">="&B22),SUMIFS(EeData!C:C,EeData!G:G,"A",EeData!E:E,">="&B22,EeData!E:E,"<"&D22))) | I22: =IF(G22 = "", "", IF(G22=0,0,$H22/$G22))
F23: Total | G23: =SUM(G7:G22) -> 37 | H23: =SUM(H7:H22) -> 3704000 | I23: =H23/G23 -> 100108.11

Sheet Grade_Report
B2: Student Grade Report
C4: Student Name | E4: Doll Woolley,Jeanne M
C6: Total Point Available | E6: 500
C7: Total Earned Points | E7: =IF(E4="","", SUM(SUMIF(Records!A16:A27, $E$4, Records!L16:L27), SUMIF(Records!A16:A27, $E$4, Records!X16:X27), SUMIF(Records!A16:A27, $E$4, Records!D16:D27), SUMIF(Records!A16:A27, $E$4, Records!E16:E27))) -> 439
C8: Achieved Percentage | E8: =IF(E4="","", E7/E6) -> 0.878
C9: Letter Grade | E9: =IF(E4="", "", INDEX(Records!B3:E12, MATCH(E8,Records!E3:E12,-1),1)) -> B
C11: Final | E11: =IF(E4="","", INDEX(Records!$A$16:$X$27, MATCH($E$4, Records!$A$16:$A$27, 0),4)) -> 190
C12: Midterm | E12: =IF(E4="", "", INDEX(Records!$A$16:$X$27, MATCH($E$4, Records!$A$16:$A$27, 0),5)) -> 96
C13: Quiz | E13: =IF(E4="", "", INDEX(Records!$A$16:$X$27, MATCH($E$4, Records!$A$16:$A$27, 0),12)) -> 104
C14: Homework | E14: =IF(E4="", "", INDEX(Records!$A$16:$X$27, MATCH($E$4, Records!$A$16:$A$27, 0),24)) -> 49

Sheet Records
A1: Grading Policy
B2: Grade | C2: Percentage
B3: A | C3: 0.95 | D3: to | E3: 1
B4: A- | C4: 0.92 | D4: to | E4: 0.9499
B5: B+ | C5: 0.9 | D5: to | E5: 0.9199
B6: B | C6: 0.85 | D6: to | E6: 0.8999
B7: B- | C7: 0.82 | D7: to | E7: 0.8499
B8: C+ | C8: 0.8 | D8: to | E8: 0.8199
B9: C | C9: 0.77 | D9: to | E9: 0.7999
B10: C- | C10: 0.75 | D10: to | E10: 0.7699
B11: D | C11: 0.65 | D11: to | E11: 0.7499
B12: F | C12: 0 | D12: to | E12: 0.6499
C14: Total | G14: Quizzes | M14: Homework
A15: Name | C15: Points | D15: Final | E15: Mid-Term | G15: 1 | H15: 2 | I15: 3 | J15: 4 | K15: 5 | L15: Total | M15: 1 | N15: 2 | O15: 3 | P15: 4 | Q15: 5 | R15: 6 | S15: 7 | T15: 8 | U15: 9 | V15: 10 | W15: 11 | X15: Total
A16: Klendshoj,Roxanne L | C16: 488 | D16: 195 | E16: 98 | G16: 24 | H16: 23 | I16: 18 | J16: 23 | K16: 21 | L16: 109 | M16: 10 | N16: 9 | O16: 7 | P16: 8 | Q16: 6 | R16: 8 | S16: 7 | T16: 6 | U16: 8 | V16: 10 | W16: 7 | X16: 86
A17: Doll Woolley,Jeanne M | C17: 439 | D17: 190 | E17: 96 | G17: 23 | H17: 22 | I17: 17 | J17: 22 | K17: 20 | L17: 104 | M17: 9 | N17: 8 | O17: 0 | P17: 7 | Q17: 0 | R17: 2 | S17: 5 | T17: 4 | U17: 6 | V17: 8 | X17: 49
A18: Bartho,Jerome F | C18: 458 | D18: 185 | E18: 94 | G18: 22 | H18: 25 | I18: 25 | J18: 25 | K18: 25 | L18: 122 | M18: 8 | N18: 7 | O18: 9 | P18: 7 | Q18: 10 | R18: 7 | S18: 3 | T18: 2 | U18: 4 | X18: 57
A19: Benson,Scott G | C19: 430 | D19: 180 | E19: 92 | G19: 21 | H19: 20 | I19: 25 | J19: 20 | K19: 22 | L19: 108 | M19: 7 | N19: 6 | O19: 8 | P19: 10 | Q19: 7 | R19: 9 | S19: 2 | T19: 1 | X19: 50
A20: Aho,Diane M | C20: 458 | D20: 198 | E20: 90 | G20: 25 | H20: 25 | I20: 25 | J20: 25 | K20: 21 | L20: 121 | M20: 6 | N20: 5 | O20: 7 | P20: 9 | Q20: 6 | R20: 8 | S20: 8 | X20: 49
A21: Larson,DeeAnn S | C21: 391 | D21: 170 | E21: 88 | G21: 19 | H21: 18 | I21: 23 | J21: 18 | K21: 20 | L21: 98 | M21: 5 | N21: 4 | O21: 6 | P21: 8 | Q21: 5 | R21: 7 | X21: 35
A22: Nelson,Susann K | C22: 420 | D22: 200 | E22: 86 | G22: 18 | H22: 17 | I22: 22 | J22: 17 | K22: 19 | L22: 93 | M22: 10 | N22: 6 | O22: 8 | P22: 10 | Q22: 7 | X22: 41
A23: Asche,Tracy A | C23: 319 | D23: 160 | E23: 84 | G23: 17 | H23: 16 | I23: 25 | K23: 2 | L23: 60 | M23: 3 | N23: 2 | O23: 4 | P23: 6 | X23: 15
A24: Carlson,Robert L | C24: 416 | D24: 200 | E24: 100 | G24: 16 | H24: 15 | I24: 20 | J24: 25 | K24: 23 | L24: 99 | M24: 10 | N24: 2 | O24: 5 | X24: 17
A25: Donovan,Richard G | C25: 305 | D25: 180 | E25: 90 | G25: 15 | L25: 15 | M25: 10 | N25: 10 | X25: 20
A26: Shapiro,Susan R | C26: 234 | D26: 145 | E26: 78 | K26: 2 | L26: 2 | M26: 9 | X26: 9
A27: Johnson,Bruce D | C27: 447 | D27: 200 | E27: 100 | G27: 13 | H27: 12 | I27: 17 | J27: 22 | K27: 20 | L27: 84 | M27: 5 | N27: 4 | O27: 6 | P27: 8 | Q27: 5 | R27: 7 | S27: 5 | T27: 4 | U27: 6 | V27: 8 | W27: 5 | X27: 63
A28: 1 | B28: 2 | C28: 3 | D28: 4 | E28: 5 | F28: 6 | G28: 7 | H28: 8 | I28: 9 | J28: 10 | K28: 11 | L28: 12 | M28: 13 | N28: 14 | O28: 15 | P28: 16 | Q28: 17 | R28: 18 | S28: 19 | T28: 20 | U28: 21 | V28: 22 | W28: 23 | X28: 24

Sheet EeData
A1: Employee Database
A5: ID | B5: Company Code | C5: Current Salary | D5: Prior Salary | E5: Age | F5: Service | G5: Status Code | H5: Prior Status
A6: 375757 | B6: 2 | C6: 96000 | D6: 91428.571 | E6: 55 | F6: 7 | G6: A | H6: A
A7: 384691 | B7: 1 | C7: 89000 | D7: 84761.905 | E7: 52 | F7: 5 | G7: A | H7: A
A8: 396332 | B8: 3 | C8: 85000 | E8: 48 | F8: 1 | G8: A
A9: 401073 | B9: 1 | D9: 80000 | E9: 66 | G9: R | H9: R
A10: 409118 | B10: 1 | C10: 83000 | D10: 71000 | E10: 28 | F10: 11 | G10: A | H10: A
A11: 411380 | B11: 1 | C11: 86000 | D11: 74000 | E11: 57 | F11: 27 | G11: A | H11: A
A12: 412092 | B12: 1 | C12: 87000 | E12: 32 | F12: 2 | G12: A
A13: 413369 | B13: 1 | C13: 86000 | E13: 44 | F13: 14 | G13: A
A14: 415179 | B14: 1 | C14: 75000 | D14: 63000 | E14: 32 | F14: 2 | G14: A | H14: A
A15: 422576 | B15: 1 | C15: 86000 | D15: 80000 | E15: 55 | G15: R | H15: A
A16: 424060 | B16: 3 | C16: 250000 | D16: 230000 | E16: 51 | F16: 10 | G16: A | H16: A
A17: 431411 | B17: 3 | C17: 91000 | D17: 86666.667 | E17: 49 | F17: 6 | G17: A | H17: A
A18: 436028 | B18: 1 | C18: 86000 | D18: 74000 | E18: 23 | F18: 3 | G18: A | H18: A
A19: 437293 | B19: 3 | C19: 86000 | D19: 80000 | E19: 51 | G19: V | H19: A
A20: 438052 | B20: 1 | C20: 86000 | D20: 74000 | E20: 32 | F20: 9 | G20: A | H20: A
A21: 438638 | B21: 2 | C21: 87000 | D21: 82857.143 | E21: 47 | F21: 12 | G21: A | H21: A
A22: 449418 | B22: 1 | C22: 76000 | D22: 64000 | E22: 45 | F22: 15 | G22: A | H22: A
A23: 449944 | B23: 1 | C23: 86000 | D23: 80000 | E23: 45 | G23: V | H23: A
A24: 452656 | B24: 2 | C24: 93000 | D24: 88571.429 | E24: 46 | F24: 18 | G24: A | H24: A
A25: 463271 | B25: 1 | C25: 54000 | D25: 42000 | E25: 32 | F25: 8 | G25: A | H25: A
A26: 463938 | B26: 1 | C26: 96000 | D26: 84000 | E26: 32 | F26: 2 | G26: A | H26: A
A27: 479102 | B27: 3 | C27: 85000 | E27: 48 | F27: 1 | G27: A
A28: 481800 | B28: 2 | D28: 80000 | E28: 64 | G28: R | H28: R
A29: 482078 | B29: 1 | C29: 110000 | D29: 98000 | E29: 32 | F29: 8 | G29: A | H29: A
A30: 486583 | B30: 1 | C30: 86000 | D30: 80000 | E30: 32 | G30: T | H30: A
A31: 492053 | B31: 1 | C31: 86000 | D31: 74000 | E31: 32 | F31: 2 | G31: A | H31: A
A32: 492133 | B32: 1 | C32: 100000 | D32: 88000 | E32: 32 | F32: 10 | G32: A | H32: A
A33: 492176 | B33: 1 | C33: 86000 | D33: 80000 | E33: 34 | G33: T | H33: A
A34: 496907 | B34: 2 | D34: 80000 | E34: 59 | G34: R | H34: V
A35: 507242 | B35: 1 | C35: 92000 | D35: 40000 | E35: 44 | F35: 7 | G35: A | H35: A
A36: 513820 | B36: 1 | D36: 80000 | E36: 62 | G36: R | H36: V
A37: 514774 | B37: 3 | D37: 80000 | E37: 44 | G37: V | H37: V
A38: 520201 | B38: 2 | D38: 80000 | E38: 36 | G38: V | H38: V
A39: 520938 | B39: 1 | C39: 23000 | D39: 11000 | E39: 36 | F39: 10 | G39: A | H39: A
A40: 521501 | B40: 1 | C40: 79000 | D40: 67000 | E40: 26 | F40: 8 | G40: A | H40: A
A41: 526149 | B41: 3 | C41: 97000 | D41: 92380.952 | E41: 55 | F41: 9 | G41: A | H41: A
A42: 539134 | B42: 1 | C42: 94000 | D42: 82000 | E42: 32 | F42: 10 | G42: A | H42: A
A43: 540346 | B43: 1 | C43: 95000 | D43: 90476.19 | E43: 49 | F43: 10 | G43: A | H43: A
...
